<?xml version="1.0" ?>
<!-- Generated using onshape-to-robot -->
<!-- Onshape https://cad.onshape.com/documents/3f7808e3432022d5b08177ae/w/13f89a95a237b65f6f12ec68/e/351cb02b91d61e28501e44e7 -->
<robot name="meca500" xmlns:xacro="http://www.ros.org/wiki/xacro">

  <xacro:arg name="use_mock_hardware" default="true"/>

  <xacro:include filename="$(find mecha500_robot)/urdf/robot.ros2_control.xacro" />

  <xacro:meca500_ros2_control name="meca500" prefix="" use_mock_hardware="$(arg use_mock_hardware)"/>

  <!-- Link link_0__base -->
  <link name="link_0__base">
    <inertial>
      <origin xyz="-0.003588 -0.0202515 -0.0487122" rpy="0 0 0"/>
      <mass value="1.90904"/>
      <inertia ixx="0.00285533" ixy="3.86058e-06" ixz="1.52473e-07" iyy="0.00224755" iyz="-0.000252565" izz="0.00266554"/>
    </inertial>
    <!-- Part link_0__base -->
    <visual>
      <origin xyz="-0.0191622 -0.00975546 -0.00283954" rpy="1.5708 -0 -3.14159"/>
      <geometry>
        <mesh filename="package://mecha500_robot/meshes/link_0__base.stl"/>
      </geometry>
      <material name="link_0__base_material">
        <color rgba="0.74902 0.74902 0.74902 1"/>
      </material>
    </visual>
    <collision>
      <origin xyz="-0.0191622 -0.00975546 -0.00283954" rpy="1.5708 -0 -3.14159"/>
      <geometry>
        <mesh filename="package://mecha500_robot/meshes/link_0__base.stl"/>
      </geometry>
    </collision>
  </link>
  <!-- Link link_1 -->
  <link name="link_1">
    <inertial>
      <origin xyz="0.00334976 -5.73436e-05 -0.0215866" rpy="0 0 0"/>
      <mass value="0.497831"/>
      <inertia ixx="0.000473161" ixy="4.22411e-06" ixz="-1.09578e-05" iyy="0.000832194" iyz="-3.07932e-07" izz="0.000761939"/>
    </inertial>
    <!-- Part link_1 -->
    <visual>
      <origin xyz="0 0 -0.045" rpy="3.14159 0 1.56059"/>
      <geometry>
        <mesh filename="package://mecha500_robot/meshes/link_1.stl"/>
      </geometry>
      <material name="link_1_material">
        <color rgba="0.74902 0.74902 0.74902 1"/>
      </material>
    </visual>
    <collision>
      <origin xyz="0 0 -0.045" rpy="3.14159 0 1.56059"/>
      <geometry>
        <mesh filename="package://mecha500_robot/meshes/link_1.stl"/>
      </geometry>
    </collision>
  </link>
  <!-- Link link_2 -->
  <link name="link_2">
    <inertial>
      <origin xyz="0.0234559 0.0324928 -0.0323826" rpy="0 0 0"/>
      <mass value="1.74151"/>
      <inertia ixx="0.00391112" ixy="-0.00160445" ixz="4.42327e-05" iyy="0.00327463" iyz="5.2002e-05" izz="0.00432559"/>
    </inertial>
    <!-- Part link_2 -->
    <visual>
      <origin xyz="-0.00530816 -0.00968086 -0.032" rpy="-3.14159 0 0.856039"/>
      <geometry>
        <mesh filename="package://mecha500_robot/meshes/link_2.stl"/>
      </geometry>
      <material name="link_2_material">
        <color rgba="0.74902 0.74902 0.74902 1"/>
      </material>
    </visual>
    <collision>
      <origin xyz="-0.00530816 -0.00968086 -0.032" rpy="-3.14159 0 0.856039"/>
      <geometry>
        <mesh filename="package://mecha500_robot/meshes/link_2.stl"/>
      </geometry>
    </collision>
  </link>
  <!-- Link link_3 -->
  <link name="link_3">
    <inertial>
      <origin xyz="0.00637687 -0.0143165 -0.0310276" rpy="0 0 0"/>
      <mass value="1.00601"/>
      <inertia ixx="0.000985393" ixy="0.000189374" ixz="9.40101e-06" iyy="0.0007538" iyz="-1.11226e-05" izz="0.00122325"/>
    </inertial>
    <!-- Part link_3 -->
    <visual>
      <origin xyz="-0.155395 0.0992203 -0.0470431" rpy="2.13905 1.5708 0"/>
      <geometry>
        <mesh filename="package://mecha500_robot/meshes/link_3.stl"/>
      </geometry>
      <material name="link_3_material">
        <color rgba="0.74902 0.74902 0.74902 1"/>
      </material>
    </visual>
    <collision>
      <origin xyz="-0.155395 0.0992203 -0.0470431" rpy="2.13905 1.5708 0"/>
      <geometry>
        <mesh filename="package://mecha500_robot/meshes/link_3.stl"/>
      </geometry>
    </collision>
  </link>
  <!-- Link link_4 -->
  <link name="link_4">
    <inertial>
      <origin xyz="7.16922e-06 -0.000731017 -0.0296473" rpy="0 0 0"/>
      <mass value="0.319243"/>
      <inertia ixx="0.000307803" ixy="-1.8448e-08" ixz="-6.729e-09" iyy="0.000187145" iyz="-3.44011e-06" izz="0.00021562"/>
    </inertial>
    <!-- Part link_4 -->
    <visual>
      <origin xyz="4.4e-06 0 -0.059" rpy="3.14159 -0 0"/>
      <geometry>
        <mesh filename="package://mecha500_robot/meshes/link_4.stl"/>
      </geometry>
      <material name="link_4_material">
        <color rgba="0.74902 0.74902 0.74902 1"/>
      </material>
    </visual>
    <collision>
      <origin xyz="4.4e-06 0 -0.059" rpy="3.14159 -0 0"/>
      <geometry>
        <mesh filename="package://mecha500_robot/meshes/link_4.stl"/>
      </geometry>
    </collision>
  </link>
  <!-- Link link_5 -->
  <link name="link_5">
    <inertial>
      <origin xyz="2.54851e-06 -0.020511 -0.023743" rpy="0 0 0"/>
      <mass value="0.447067"/>
      <inertia ixx="0.000325043" ixy="-2.2551e-08" ixz="8.77e-09" iyy="0.000149997" iyz="-9.46566e-06" izz="0.000314979"/>
    </inertial>
    <!-- Part link_5 -->
    <visual>
      <origin xyz="-0.222375 0.12 -0.0397931" rpy="1.5708 1.5708 0"/>
      <geometry>
        <mesh filename="package://mecha500_robot/meshes/link_5.stl"/>
      </geometry>
      <material name="link_5_material">
        <color rgba="0.74902 0.74902 0.74902 1"/>
      </material>
    </visual>
    <collision>
      <origin xyz="-0.222375 0.12 -0.0397931" rpy="1.5708 1.5708 0"/>
      <geometry>
        <mesh filename="package://mecha500_robot/meshes/link_5.stl"/>
      </geometry>
    </collision>
  </link>
  <!-- Link link_6__flange -->
  <link name="link_6__flange">
    <inertial>
      <origin xyz="-5.182e-09 -3.0509e-06 -0.00515374" rpy="0 0 0"/>
      <mass value="0.00865395"/>
      <inertia ixx="3.06713e-07" ixy="0" ixz="-0" iyy="2.99295e-07" iyz="-1.22e-10" izz="4.44177e-07"/>
    </inertial>
    <!-- Part link_6__flange -->
    <visual>
      <origin xyz="-0.0763536 -0.0515492 0.158594" rpy="3.14159 0 0"/>
      <geometry>
        <mesh filename="package://mecha500_robot/meshes/link_6__flange.stl"/>
      </geometry>
      <material name="link_6__flange_material">
        <color rgba="0.74902 0.74902 0.74902 1"/>
      </material>
    </visual>
    <collision>
      <origin xyz="-0.0763536 -0.0515492 0.158594" rpy="3.14159 0 0"/>
      <geometry>
        <mesh filename="package://mecha500_robot/meshes/link_6__flange.stl"/>
      </geometry>
    </collision>
  </link>
  <!-- Joint from link_5 to link_6__flange -->
  <joint name="joint6" type="revolute">
    <origin xyz="2.2e-06 -0.059 -0.02425" rpy="1.5708 0.00776461 3.14159"/>
    <parent link="link_5"/>
    <child link="link_6__flange"/>
    <axis xyz="0 0 1"/>
    <limit effort="1.5" velocity="8.7266" lower="-628.318" upper="628.318"/>
    <joint_properties friction="0.0"/>
  </joint>
  <!-- Joint from link_4 to link_5 -->
  <joint name="joint5" type="revolute">
    <origin xyz="4.4e-06 -0.0245 -0.059" rpy="1.5708 0.0574563 -0"/>
    <parent link="link_4"/>
    <child link="link_5"/>
    <axis xyz="0 0 1"/>
    <limit effort="2.5" velocity="6.1087" lower="-2.0071" upper="2.0071"/>
    <joint_properties friction="0.0"/>
  </joint>
  <!-- Joint from link_3 to link_4 -->
  <joint name="joint4" type="revolute">
    <origin xyz="0.00296752 -0.0659636 -0.0315" rpy="-1.5708 1.44617 -0.56825"/>
    <parent link="link_3"/>
    <child link="link_4"/>
    <axis xyz="0 0 1"/>
    <limit effort="2.5" velocity="6.1087" lower="-2.9671" upper="2.9671"/>
    <joint_properties friction="0.0"/>
  </joint>
  <!-- Joint from link_2 to link_3 -->
  <joint name="joint3" type="revolute">
    <origin xyz="0.0831754 0.0922782 -0" rpy="0 0 0.856039"/>
    <parent link="link_2"/>
    <child link="link_3"/>
    <axis xyz="0 0 1"/>
    <limit effort="16.6" velocity="3.927" lower="-2.3562" upper="1.2217"/>
    <joint_properties friction="0.0"/>
  </joint>
  <!-- Joint from link_1 to link_2 -->
  <joint name="joint2" type="revolute">
    <origin xyz="-0.0324983 0.000331735 -0.045" rpy="-1.5708 0 1.56059"/>
    <parent link="link_1"/>
    <child link="link_2"/>
    <axis xyz="0 0 1"/>
    <limit effort="16.6" velocity="3.927" lower="-1.2217" upper="1.5708"/>
    <joint_properties friction="0.0"/>
  </joint>
  <!-- Joint from link_0__base to link_1 -->
  <joint name="joint1" type="revolute">
    <origin xyz="-0.00361915 -0.00975546 0.00153062" rpy="-3.14159 -0 -3.14159"/>
    <parent link="link_0__base"/>
    <child link="link_1"/>
    <axis xyz="0 0 1"/>
    <limit effort="16.6" velocity="3.927" lower="-3.0543" upper="3.0543"/>
    <joint_properties friction="0.0"/>
  </joint>
</robot>
